<robot name="manipulator">

<material name="dark-gray">
    <color rgba="0.3 0.3 0.3 1" />
</material>
<material name="light-gray">
    <color rgba="0.7 0.7 0.7 1" />
</material>

<link name="turntable">
    <inertial>
        <origin rpy="0 0 0" xyz="0 0 0.025" />
        <mass value="1" />
        <inertia ixx="0.0" ixy="0.0" ixz="0.0" iyy="0.0" iyz="0.0" izz="0.0" />
    </inertial>
    <visual name="">
        <geometry>
            <cylinder radius="0.2" length="0.05" />
        </geometry>
        <material name="dark-gray" />
        <origin rpy="0 0 0" xyz="0 0 0.025" />
    </visual>
    <collision name="">
        <geometry>
           <cylinder radius="0.2" length="0.05" />
        </geometry>
        <origin rpy="0 0 0" xyz="0 0 0.025" />
    </collision>
</link>

<link name="base1">
    <inertial>
        <origin rpy="0 0 0" xyz="0 0 0.2" />
        <mass value="1" />
        <inertia ixx="0.0" ixy="0.0" ixz="0.0" iyy="0.0" iyz="0.0" izz="0.0" />
    </inertial>
    <visual name="">
        <geometry>
            <cylinder radius="0.15" length="0.3" />
        </geometry>
        <material name="dark-gray" />
        <origin rpy="0 0 0" xyz="0 0 0.2" />
    </visual>
    <collision name="">
        <geometry>
           <cylinder radius="0.15" length="0.3" />
        </geometry>
        <origin rpy="0 0 0" xyz="0 0 0.2" />
    </collision>
</link>

<link name="base2">
    <inertial>
        <origin rpy="0 1.57 0" xyz="0.075 0 0.2" />
        <mass value="1" />
        <inertia ixx="0.0" ixy="0.0" ixz="0.0" iyy="0.0" iyz="0.0" izz="0.0" />
    </inertial>
    <visual name="">
        <geometry>
            <cylinder radius="0.15" length="0.15" />
        </geometry>
        <material name="dark-gray" />
        <origin rpy="0 1.57 0" xyz="0.075 0 0.2" />
    </visual>
    <collision name="">
        <geometry>
           <cylinder radius="0.15" length="0.15" />
        </geometry>
        <origin rpy="0 1.57 0" xyz="0.075 0 0.2" />
    </collision>
</link>

<link name="shoulder1">
    <inertial>
        <origin rpy="0 1.57 0" xyz="0.3 0 0" />
        <mass value="1" />
        <inertia ixx="0.0" ixy="0.0" ixz="0.0" iyy="0.0" iyz="0.0" izz="0.0" />
    </inertial>
    <visual name="">
        <geometry>
            <cylinder radius="0.15" length="0.3" />
        </geometry>
        <material name="dark-gray" />
        <origin rpy="0 1.57 0" xyz="0.3 0 0" />
    </visual>
    <collision name="">
        <geometry>
           <cylinder radius="0.15" length="0.3" />
        </geometry>
        <origin rpy="0 1.57 0" xyz="0.3 0 0" />
    </collision>
</link>

<link name="shoulder2">
    <inertial>
        <origin rpy="0 0 0" xyz="0.3 0 0.075" />
        <mass value="1" />
        <inertia ixx="0.0" ixy="0.0" ixz="0.0" iyy="0.0" iyz="0.0" izz="0.0" />
    </inertial>
    <visual name="">
        <geometry>
            <cylinder radius="0.15" length="0.15" />
        </geometry>
        <material name="dark-gray" />
        <origin rpy="0 0 0" xyz="0.3 0 0.075" />
    </visual>
    <collision name="">
        <geometry>
           <cylinder radius="0.15" length="0.15" />
        </geometry>
        <origin rpy="0 0 0" xyz="0.3 0 0.075" />
    </collision>
</link>

<link name="lower-arm">
    <inertial>
        <origin rpy="0 0 0" xyz="0.3 0 0.55" />
        <mass value="1" />
        <inertia ixx="0.0" ixy="0.0" ixz="0.0" iyy="0.0" iyz="0.0" izz="0.0" />
    </inertial>
    <visual name="">
        <geometry>
            <cylinder radius="0.125" length="0.8" />
        </geometry>
        <material name="light-gray" />
        <origin rpy="0 0 0" xyz="0.3 0 0.55" />
    </visual>
    <collision name="">
        <geometry>
           <cylinder radius="0.125" length="0.8" />
        </geometry>
        <origin rpy="0 0 0" xyz="0.3 0 0.55" />
    </collision>
</link>

<link name="lower-elbow1">
    <inertial>
        <origin rpy="0 0 0" xyz="0.3 0 1.025" />
        <mass value="1" />
        <inertia ixx="0.0" ixy="0.0" ixz="0.0" iyy="0.0" iyz="0.0" izz="0.0" />
    </inertial>
    <visual name="">
        <geometry>
            <cylinder radius="0.15" length="0.15" />
        </geometry>
        <material name="dark-gray" />
        <origin rpy="0 0 0" xyz="0.3 0 1.025" />
    </visual>
    <collision name="">
        <geometry>
            <cylinder radius="0.15" length="0.15" />
        </geometry>
        <origin rpy="0 0 0" xyz="0.3 0 1.025" />
    </collision>
</link>

<link name="lower-elbow2">
    <inertial>
        <origin rpy="0 1.57 0" xyz="0.3 0 1.1" />
        <mass value="1" />
        <inertia ixx="0.0" ixy="0.0" ixz="0.0" iyy="0.0" iyz="0.0" izz="0.0" />
    </inertial>
    <visual name="">
        <geometry>
            <cylinder radius="0.15" length="0.3" />
        </geometry>
        <material name="dark-gray" />
        <origin rpy="0 1.57 0" xyz="0.3 0 1.1" />
    </visual>
    <collision name="">
        <geometry>
            <cylinder radius="0.15" length="0.3" />
        </geometry>
        <origin rpy="0 1.57 0" xyz="0.3 0 1.1" />
    </collision>
</link>

<link name="upper-elbow1">
    <inertial>
        <origin rpy="0 1.57 0" xyz="0.075 0 0" />
        <mass value="1" />
        <inertia ixx="0.0" ixy="0.0" ixz="0.0" iyy="0.0" iyz="0.0" izz="0.0" />
    </inertial>
    <visual name="">
        <geometry>
            <cylinder radius="0.15" length="0.15" />
        </geometry>
        <material name="dark-gray" />
        <origin rpy="0 1.57 0" xyz="0.075 0 0" />
    </visual>
    <collision name="">
        <geometry>
            <cylinder radius="0.15" length="0.15" />
        </geometry>
        <origin rpy="0 1.57 0" xyz="0.075 0 0" />
    </collision>
</link>

<link name="upper-elbow2">
    <inertial>
        <origin rpy="0 1.57 0" xyz="0 0 0" />
        <mass value="1" />
        <inertia ixx="0.0" ixy="0.0" ixz="0.0" iyy="0.0" iyz="0.0" izz="0.0" />
    </inertial>
    <visual name="">
        <geometry>
            <sphere radius="0.15" />
        </geometry>
        <material name="dark-gray" />
        <origin rpy="0 1.57 0" xyz="0 0 0" />
    </visual>
    <collision name="">
        <geometry>
            <sphere radius="0.15" />
        </geometry>
        <origin rpy="0 1.57 0" xyz="0 0 0" />
    </collision>
</link>

<link name="upper-elbow3">
    <inertial>
        <origin rpy="1.57 0 0" xyz="0 0.075 0" />
        <mass value="1" />
        <inertia ixx="0.0" ixy="0.0" ixz="0.0" iyy="0.0" iyz="0.0" izz="0.0" />
    </inertial>
    <visual name="">
        <geometry>
            <cylinder radius="0.15" length="0.15" />
        </geometry>
        <material name="dark-gray" />
        <origin rpy="1.57 0 0" xyz="0 0.075 0" />
    </visual>
    <collision name="">
        <geometry>
            <cylinder radius="0.15" length="0.15" />
        </geometry>
        <origin rpy="1.57 0 0" xyz="0 0.075 0" />
    </collision>
</link>

<link name="upper-arm">
    <inertial>
        <origin rpy="1.57 0 0" xyz="0 0.55 0" />
        <mass value="1" />
        <inertia ixx="0.0" ixy="0.0" ixz="0.0" iyy="0.0" iyz="0.0" izz="0.0" />
    </inertial>
    <visual name="">
        <geometry>
            <cylinder radius="0.125" length="0.8" />
        </geometry>
        <material name="light-gray" />
        <origin rpy="1.57 0 0" xyz="0 0.55 0" />
    </visual>
    <collision name="">
        <geometry>
            <cylinder radius="0.125" length="0.8" />
        </geometry>
        <origin rpy="1.57 0 0" xyz="0 0.55 0" />
    </collision>
</link>

<link name="lower-wrist1">
    <inertial>
        <origin rpy="1.57 0 0" xyz="0 1.0125 0" />
        <mass value="1" />
        <inertia ixx="0.0" ixy="0.0" ixz="0.0" iyy="0.0" iyz="0.0" izz="0.0" />
    </inertial>
    <visual name="">
        <geometry>
            <cylinder radius="0.125" length="0.125" />
        </geometry>
        <material name="dark-gray" />
        <origin rpy="1.57 0 0" xyz="0 1.0125 0" />
    </visual>
    <collision name="">
        <geometry>
            <cylinder radius="0.125" length="0.125" />
        </geometry>
        <origin rpy="1.57 0 0" xyz="0 1.0125 0" />
    </collision>
</link>

<link name="lower-wrist2">
    <inertial>
        <origin rpy="0 1.57 0" xyz="0 1.075 0" />
        <mass value="1" />
        <inertia ixx="0.0" ixy="0.0" ixz="0.0" iyy="0.0" iyz="0.0" izz="0.0" />
    </inertial>
    <visual name="">
        <geometry>
            <cylinder radius="0.125" length="0.25" />
        </geometry>
        <material name="dark-gray" />
        <origin rpy="0 1.57 0" xyz="0 1.075 0" />
    </visual>
    <collision name="">
        <geometry>
            <cylinder radius="0.125" length="0.25" />
        </geometry>
        <origin rpy="0 1.57 0" xyz="0 1.075 0" />
    </collision>
</link>

<link name="mid-wrist1">
    <inertial>
        <origin rpy="0 1.57 0" xyz="0.1875 0 0" />
        <mass value="1" />
        <inertia ixx="0.0" ixy="0.0" ixz="0.0" iyy="0.0" iyz="0.0" izz="0.0" />
    </inertial>
    <visual name="">
        <geometry>
            <cylinder radius="0.125" length="0.125" />
        </geometry>
        <material name="dark-gray" />
        <origin rpy="0 1.57 0" xyz="0.1875 0 0" />
    </visual>
    <collision name="">
        <geometry>
            <cylinder radius="0.125" length="0.125" />
        </geometry>
        <origin rpy="0 1.57 0" xyz="0.1875 0 0" />
    </collision>
</link>

<link name="mid-wrist2">
    <inertial>
        <origin rpy="1.57 0 0" xyz="0.25 0 0" />
        <mass value="1" />
        <inertia ixx="0.0" ixy="0.0" ixz="0.0" iyy="0.0" iyz="0.0" izz="0.0" />
    </inertial>
    <visual name="">
        <geometry>
            <cylinder radius="0.125" length="0.25" />
        </geometry>
        <material name="dark-gray" />
        <origin rpy="1.57 0 0" xyz="0.25 0 0" />
    </visual>
    <collision name="">
        <geometry>
            <cylinder radius="0.125" length="0.25" />
        </geometry>
        <origin rpy="1.57 0 0" xyz="0.25 0 0" />
    </collision>
</link>

<link name="upper-wrist1">
    <inertial>
        <origin rpy="1.57 0 0" xyz="0 0.1875 0" />
        <mass value="1" />
        <inertia ixx="0.0" ixy="0.0" ixz="0.0" iyy="0.0" iyz="0.0" izz="0.0" />
    </inertial>
    <visual name="">
        <geometry>
            <cylinder radius="0.125" length="0.125" />
        </geometry>
        <material name="dark-gray" />
        <origin rpy="1.57 0 0" xyz="0 0.1875 0" />
    </visual>
    <collision name="">
        <geometry>
            <cylinder radius="0.125" length="0.125" />
        </geometry>
        <origin rpy="1.57 0 0" xyz="0 0.1875 0" />
    </collision>
</link>

<link name="upper-wrist2">
    <inertial>
        <origin rpy="0 0 0" xyz="0 0.25 0" />
        <mass value="1" />
        <inertia ixx="0.0" ixy="0.0" ixz="0.0" iyy="0.0" iyz="0.0" izz="0.0" />
    </inertial>
    <visual name="">
        <geometry>
            <cylinder radius="0.125" length="0.25" />
        </geometry>
        <material name="dark-gray" />
        <origin rpy="0 0 0" xyz="0 0.25 0" />
    </visual>
    <collision name="">
        <geometry>
            <cylinder radius="0.125" length="0.25" />
        </geometry>
        <origin rpy="0 0 0" xyz="0 0.25 0" />
    </collision>
</link>

<joint name="turntable-base" type="revolute">
    <origin rpy="0 0 0" xyz="0 0 0" />
    <parent link="turntable" />
    <child link="base1" />
    <axis xyz="0 0 1" />
    <limit effort="1000" lower="-6.28" upper="6.28" velocity="1" />
</joint>

<joint name="base" type="fixed">
    <origin rpy="0 0 0" xyz="0 0 0" />
    <parent link="base1" />
    <child link="base2" />
</joint>

<joint name="base-shoulder" type="revolute">
    <origin rpy="0 0 0" xyz="0 0 0.2" />
    <parent link="base2" />
    <child link="shoulder1" />
    <axis xyz="1 0 0" />
    <limit effort="1000" lower="-1.57" upper="1.57" velocity="1" />
</joint>

<joint name="shoulder" type="fixed">
    <origin rpy="0 0 0" xyz="0 0 0" />
    <parent link="shoulder1" />
    <child link="shoulder2" />
</joint>

<joint name="shoulder-lower-arm" type="fixed">
    <origin rpy="0 0 0" xyz="0 0 0" />
    <parent link="shoulder2" />
    <child link="lower-arm" />
</joint>

<joint name="lower-arm-elbow" type="fixed">
    <origin rpy="0 0 0" xyz="0 0 0" />
    <parent link="lower-arm" />
    <child link="lower-elbow1" />
</joint>

<joint name="lower-elbow" type="fixed">
    <origin rpy="0 0 0" xyz="0 0 0" />
    <parent link="lower-elbow1" />
    <child link="lower-elbow2" />
</joint>

<joint name="elbow" type="revolute">
    <origin rpy="0 0 0" xyz="0 0 1.1" />
    <parent link="lower-elbow2" />
    <child link="upper-elbow1" />
    <axis xyz="1 0 0" />
    <limit effort="1000" lower="-1.57" upper="1.57" velocity="1" />
</joint>

<joint name="upper-elbow1" type="fixed">
    <origin rpy="0 0 0" xyz="0 0 0" />
    <parent link="upper-elbow1" />
    <child link="upper-elbow2" />
</joint>

<joint name="upper-elbow2" type="fixed">
    <origin rpy="0 0 0" xyz="0 0 0" />
    <parent link="upper-elbow2" />
    <child link="upper-elbow3" />
</joint>

<joint name="elbow-upper-arm" type="fixed">
    <origin rpy="0 0 0" xyz="0 0 0" />
    <parent link="upper-elbow3" />
    <child link="upper-arm" />
</joint>

<joint name="upper-arm-wrist" type="fixed">
    <origin rpy="0 0 0" xyz="0 0 0" />
    <parent link="upper-arm" />
    <child link="lower-wrist1" />
</joint>

<joint name="lower-wrist" type="fixed">
    <origin rpy="0 0 0" xyz="0 0 0" />
    <parent link="lower-wrist1" />
    <child link="lower-wrist2" />
</joint>

<joint name="wrist1" type="revolute">
    <origin rpy="0 0 0" xyz="0 1.075 0" />
    <parent link="lower-wrist2" />
    <child link="mid-wrist1" />
    <axis xyz="1 0 0" />
    <limit effort="1000" lower="-1.57" upper="1.57" velocity="1" />
</joint>

<joint name="mid-wrist" type="fixed">
    <origin rpy="0 0 0" xyz="0 0 0" />
    <parent link="mid-wrist1" />
    <child link="mid-wrist2" />
</joint>

<joint name="wrist2" type="revolute">
    <origin rpy="0 0 0" xyz="0.25 0 0" />
    <parent link="mid-wrist2" />
    <child link="upper-wrist1" />
    <axis xyz="0 1 0" />
    <limit effort="1000" lower="-1.57" upper="1.57" velocity="1" />
</joint>

<joint name="upper-wrist" type="fixed">
    <origin rpy="0 0 0" xyz="0 0 0" />
    <parent link="upper-wrist1" />
    <child link="upper-wrist2" />
</joint>

</robot>