<?xml version="1.0"?>
<robot xmlns:xacro="http://wiki.ros.org/xacro" name="my_scara">
  
  <!-- parametry xacro -->
  <xacro:property name="wysokosc_bazy" value="1"/>
  <xacro:property name="promien_bazy" value="0.1"/>
  <xacro:property name="masa_bazy" value="10"/>
  <xacro:property name="dlugosc_ramienia_1" value="1"/>
  <xacro:property name="dlugosc_ramienia_2" value="1"/>
  <xacro:property name="szerokosc_ramienia" value="0.2"/>
  <xacro:property name="wysokosc_ramienia" value="0.1"/>
  <xacro:property name="masa_ramienia_1" value="10"/>
  <xacro:property name="masa_ramienia_2" value="10"/>
  <xacro:property name="dlugosc_kolumny" value="1"/>
  <xacro:property name="promien_kolumny" value="0.025"/>
  <xacro:property name="masa_kolumny" value="5"/>
  
  <!-- makra xacro -->
  <xacro:macro name="cylinder_inercja" params="m R L">
    <inertia ixx="${0.0833333*m*(3*R*R+L*L)}" ixy="0" ixz="0" iyy="${0.0833333*m*(3*R*R+L*L)}" iyz="0" izz="${0.5*m*R*R}"/>
  </xacro:macro>
  
  <xacro:macro name="pudelko_inercja" params="m x y z">
    <inertia ixx="${0.0833333*m*(y*y+z*z)}" ixy="0" ixz="0" iyy="${0.0833333*m*(x*x+z*z)}" iyz="0" izz="${0.0833333*m*(y*y+x*x)}"/>
  </xacro:macro>
  
  <!-- materialy -->
  <material name="red">
    <color rgba="1.0 0.0 0.0 1.0"/>
  </material>
  
  <material name="green">
    <color rgba="0.0 1.0 0.0 1.0"/>
  </material>
  
  <material name="blue">
    <color rgba="0.0 0.0 1.0 1.0"/>
  </material>
  
  
  <!-- czlony -->
  <link name="base_link">
    <visual>
      <geometry>
        <cylinder length="${wysokosc_bazy}" radius="${promien_bazy}"/>
      </geometry>
      <origin rpy="0 0 0" xyz="0 0 ${wysokosc_bazy/2}"/>
      <material name="red"/>
    </visual>
    <collision>
      <geometry>
        <cylinder length="${wysokosc_bazy}" radius="${promien_bazy}"/>
      </geometry>
      <origin rpy="0 0 0" xyz="0 0 ${wysokosc_bazy/2}"/>
    </collision>
    <inertial>
      <origin rpy="0 0 0" xyz="0 0 ${wysokosc_bazy/2}"/>
      <mass value="${masa_bazy}"/>
      <xacro:cylinder_inercja m="${masa_bazy}" R="${promien_bazy}" L="${wysokosc_bazy}"/>
    </inertial>
  </link>
  
  <link name="arm_link">
    <visual>
      <geometry>
        <box size="${dlugosc_ramienia_1} ${szerokosc_ramienia} ${wysokosc_ramienia}"/>
      </geometry>
      <origin rpy="0 0 0" xyz="${dlugosc_ramienia_1/2} 0 ${wysokosc_ramienia/2}"/>
      <material name="green"/>
    </visual>
    <collision>
      <geometry>
        <box size="${dlugosc_ramienia_1} ${szerokosc_ramienia} ${wysokosc_ramienia}"/>
      </geometry>
      <origin rpy="0 0 0" xyz="${dlugosc_ramienia_1/2} 0 ${wysokosc_ramienia/2}"/>
    </collision>
    <inertial>
      <origin rpy="0 0 0" xyz="${dlugosc_ramienia_1/2} 0 ${wysokosc_ramienia/2}"/>
      <mass value="${masa_ramienia_1}"/>
      <xacro:pudelko_inercja m="${masa_ramienia_1}" x="${dlugosc_ramienia_1}" y="${szerokosc_ramienia}" z="${wysokosc_ramienia}"/>
    </inertial>
  </link>
  
  <link name="forearm_link">
    <visual>
      <geometry>
        <box size="${dlugosc_ramienia_2} ${szerokosc_ramienia} ${wysokosc_ramienia}"/>
      </geometry>
      <origin rpy="0 0 0" xyz="${dlugosc_ramienia_2/2} 0 ${wysokosc_ramienia/2}"/>
      <material name="blue"/>
    </visual>
    <collision>
      <geometry>
        <box size="${dlugosc_ramienia_2} ${szerokosc_ramienia} ${wysokosc_ramienia}"/>
      </geometry>
      <origin rpy="0 0 0" xyz="${dlugosc_ramienia_2/2} 0 ${wysokosc_ramienia/2}"/>
    </collision>
    <inertial>
      <origin rpy="0 0 0" xyz="${dlugosc_ramienia_2/2} 0 ${wysokosc_ramienia/2}"/>
      <mass value="${masa_ramienia_2}"/>
      <xacro:pudelko_inercja m="${masa_ramienia_2}" x="${dlugosc_ramienia_2}" y="${szerokosc_ramienia}" z="${wysokosc_ramienia}"/>
    </inertial>
  </link>
  
  <link name="column_link">
    <visual>
      <geometry>
        <cylinder length="${dlugosc_kolumny}" radius="${promien_kolumny}"/>
      </geometry>
      <origin rpy="0 0 0" xyz="0 0 ${-dlugosc_kolumny/2}"/>
      <material name="red"/>
    </visual>
    <collision>
      <geometry>
        <cylinder length="${dlugosc_kolumny}" radius="${promien_kolumny}"/>
      </geometry>
      <origin rpy="0 0 0" xyz="0 0 ${-dlugosc_kolumny/2}"/>
    </collision>
    <inertial>
      <origin rpy="0 0 0" xyz="0 0 ${-dlugosc_kolumny/2}"/>
      <mass value="${masa_kolumny}"/>
      <xacro:cylinder_inercja m="${masa_kolumny}" R="${promien_kolumny}" L="${dlugosc_kolumny}"/>
    </inertial>
  </link>
  
  
  <!-- zlacza -->
  <joint name="shoulder_joint" type="revolute">
    <parent link="base_link"/>
    <child link="arm_link"/>
    <axis xyz="0 0 1"/>
    <origin rpy="0 0 0" xyz="0 0 1"/>
    <limit effort="1000.0" lower="-6.28" upper="6.28" velocity="1.0"/>
  </joint>
  
  <joint name="elbow_joint" type="revolute">
    <parent link="arm_link"/>
    <child link="forearm_link"/>
    <axis xyz="0 0 1"/>
    <origin rpy="0 0 0" xyz="1 0 -0.1"/>
    <limit effort="1000.0" lower="-6.28" upper="6.28" velocity="1.0"/>
  </joint>
  
  <joint name="wrist_joint" type="prismatic">
    <parent link="forearm_link"/>
    <child link="column_link"/>
    <axis xyz="0 0 1"/>
    <origin rpy="3.1416 0 0" xyz="1 0 0"/>
    <limit effort="1000.0" lower="0" upper="0.9" velocity="10.0"/>
  </joint>
  
</robot>
