<?xml version="1.0"?>
<robot name="my_scara">
  
  <!-- materialy -->
  <material name="red">
    <color rgba="1.0 0.0 0.0 1.0"/>
  </material>
  
  <material name="green">
    <color rgba="0.0 1.0 0.0 1.0"/>
  </material>
  
  <material name="blue">
    <color rgba="0.0 0.0 1.0 1.0"/>
  </material>
  
  
  <!-- czlony -->
  <link name="base_link">
    <visual>
      <geometry>
        <cylinder length="1" radius="0.1"/>
      </geometry>
      <origin rpy="0 0 0" xyz="0 0 0.5"/>
      <material name="red"/>
    </visual>
    <collision>
      <geometry>
        <cylinder length="1" radius="0.1"/>
      </geometry>
      <origin rpy="0 0 0" xyz="0 0 0.5"/>
    </collision>
    <inertial>
      <origin rpy="0 0 0" xyz="0 0 0.5"/>
      <mass value="10"/>
      <inertia ixx="0.86" ixy="0" ixz="0" iyy="0.86" iyz="0" izz="0.05"/>
    </inertial>
  </link>
  
  <link name="arm_link">
    <visual>
      <geometry>
        <box size="1.2 0.2 0.1"/>
      </geometry>
      <origin rpy="0 0 0" xyz="0.5 0 0.05"/>
      <material name="green"/>
    </visual>
    <collision>
      <geometry>
        <box size="1.2 0.2 0.1"/>
      </geometry>
      <origin rpy="0 0 0" xyz="0.5 0 0.05"/>
    </collision>
    <inertial>
      <origin rpy="0 0 0" xyz="0.5 0 0.05"/>
      <mass value="10"/>
      <inertia ixx="0.042" ixy="0" ixz="0" iyy="1.21" iyz="0" izz="1.23"/>
    </inertial>
  </link>
  
  <link name="forearm_link">
    <visual>
      <geometry>
        <box size="1.2 0.2 0.1"/>
      </geometry>
      <origin rpy="0 0 0" xyz="0.5 0 0.05"/>
      <material name="blue"/>
    </visual>
    <collision>
      <geometry>
        <box size="1.2 0.2 0.1"/>
      </geometry>
      <origin rpy="0 0 0" xyz="0.5 0 0.05"/>
    </collision>
    <inertial>
      <origin rpy="0 0 0" xyz="0.5 0 0.05"/>
      <mass value="10"/>
      <inertia ixx="0.042" ixy="0" ixz="0" iyy="1.21" iyz="0" izz="1.23"/>
    </inertial>
  </link>
  
  <link name="column_link">
    <visual>
      <geometry>
        <cylinder length="1" radius="0.025"/>
      </geometry>
      <origin rpy="0 0 0" xyz="0 0 -0.5"/>
      <material name="red"/>
    </visual>
    <collision>
      <geometry>
        <cylinder length="1" radius="0.025"/>
      </geometry>
      <origin rpy="0 0 0" xyz="0 0 -0.5"/>
    </collision>
    <inertial>
      <origin rpy="0 0 0" xyz="0 0 -0.5"/>
      <mass value="5"/>
      <inertia ixx="0.42" ixy="0" ixz="0" iyy="0.42" iyz="0" izz="0.0016"/>
    </inertial>
  </link>
  
  
  <!-- zlacza -->
  <joint name="shoulder_joint" type="revolute">
    <parent link="base_link"/>
    <child link="arm_link"/>
    <axis xyz="0 0 1"/>
    <origin rpy="0 0 0" xyz="0 0 1"/>
    <limit effort="1000.0" lower="-6.28" upper="6.28" velocity="1.0"/>
  </joint>
  
  <joint name="elbow_joint" type="revolute">
    <parent link="arm_link"/>
    <child link="forearm_link"/>
    <axis xyz="0 0 1"/>
    <origin rpy="0 0 0" xyz="1 0 -0.1"/>
    <limit effort="1000.0" lower="-6.28" upper="6.28" velocity="1.0"/>
  </joint>
  
  <joint name="wrist_joint" type="prismatic">
    <parent link="forearm_link"/>
    <child link="column_link"/>
    <axis xyz="0 0 1"/>
    <origin rpy="3.1416 0 0" xyz="1 0 0"/>
    <limit effort="1000.0" lower="0" upper="0.9" velocity="10.0"/>
  </joint>
  
</robot>
