<?xml version="1.0"?>
<robot xmlns:xacro="http://wiki.ros.org/xacro" name="moj_robot">

	<xacro:macro name="cylinder_inercja" params="m R L">
    <inertia ixx="${0.0833333*m*(3*R*R+L*L)}" ixy="0" ixz="0" iyy="${0.0833333*m*(3*R*R+L*L)}" iyz="0" izz="${0.5*m*R*R}"/>
  </xacro:macro>

	<link name="podstawa">
		<visual>
			<origin xyz="0 0 0" rpy="0 0 0"/>
			<geometry>
				<cylinder length="0.1" radius="0.1"/>
			</geometry>
			<material name="blue">
				<color rgba="0.25 0.6 0.9 1"/>
			</material>
		</visual>

		<collision>
			<geometry>
				<cylinder length="0.1" radius="0.1"/>
			</geometry>
			<origin rpy="0 0 0" xyz="0 0 0"/>
		</collision>
		   <inertial>
				<origin rpy="0 0 0" xyz="0 0 0.05"/>
				<mass value="1"/>
				<xacro:cylinder_inercja m="1" R="0.1" L="0.1"/>
			</inertial>
	</link>

	<link name="link_1">
		<visual>
			<origin xyz="0 0 0.1" rpy="0 0 0"/>
			<geometry>
				<cylinder length="0.1" radius="0.1"/>
			</geometry>
			<material name="grey">
				<color rgba="0.53 0.55 0.55 1"/>
			</material>
		</visual>

		<collision>
			<geometry>
				<cylinder length="0.1" radius="0.1"/>
			</geometry>
			<origin rpy="0 0 0" xyz="0 0 0.1"/>
		</collision>
		   <inertial>
				<origin rpy="0 0 0" xyz="0 0.0 0.1"/>
				<mass value="1"/>
				<xacro:cylinder_inercja m="1" R="0.1" L="0.1"/>
			</inertial>
	</link>


	<link name="link_2">
		<visual>
			<origin xyz="0 0.2 0.5" rpy="0 0 0"/>
			<geometry>
				<cylinder length="1" radius="0.1"/>
			</geometry>
			<material name="grey">
				<color rgba="0.53 0.55 0.55 1"/>
			</material>
		</visual>

		<collision>
			<geometry>
				<cylinder length="1" radius="0.1"/>
			</geometry>
			<origin rpy="0 0 0" xyz="0 0.2 0.5"/>
		</collision>
		   <inertial>
				<origin rpy="0 0 0" xyz="0 0.2 0.5"/>
				<mass value="1"/>
				<xacro:cylinder_inercja m="1" R="0.1" L="1"/>
			</inertial>
	</link>

	<link name="link_3">
		<visual>
			<origin xyz="0 0 0.2" rpy="0 0 0"/>
			<geometry>
				<cylinder length="0.5" radius="0.1"/>
			</geometry>
			<material name="grey">
				<color rgba="0.53 0.55 0.55 1"/>
			</material>
		</visual>

		<collision>
			<geometry>
				<cylinder length="0.5" radius="0.1"/>
			</geometry>
			<origin rpy="0 0 0" xyz="0 0 0.2"/>
		</collision>
		   <inertial>
				<origin rpy="0 0 0" xyz="0 0 0.2"/>
				<mass value="1"/>
				<xacro:cylinder_inercja m="1" R="0.1" L="0.5"/>
			</inertial>
	</link>

	<link name="link_4">
		<visual>
			<origin xyz="0 -0.1 0" rpy="0 0 0"/>
			<geometry>
				<cylinder length="0.3" radius="0.1"/>
			</geometry>
			<material name="grey">
				<color rgba="0.53 0.55 0.55 1"/>
			</material>
		</visual>

		<collision>
			<geometry>
				<cylinder length="0.3" radius="0.1"/>
			</geometry>
			<origin rpy="0 0 0" xyz="0 -0.1 0"/>
		</collision>
		   <inertial>
				<origin rpy="0 0 0" xyz="0 -0.1 0"/>
				<mass value="1"/>
				<xacro:cylinder_inercja m="1" R="0.1" L="0.3"/>
			</inertial>
	</link>

		<link name="link_5">
		<visual>
			<origin xyz="0 0 0" rpy="0 0 0"/>
			<geometry>
				<cylinder length="0.2" radius="0.1"/>
			</geometry>
			<material name="blue">
				<color rgba="0.25 0.6 0.9 1"/>
			</material>
		</visual>

		<collision>
			<geometry>
				<cylinder length="0.2" radius="0.1"/>
			</geometry>
			<origin rpy="0 0 0" xyz="0 0 0.0"/>
		</collision>
		   <inertial>
				<origin rpy="0 0 0" xyz="0 0 0"/>
				<mass value="1"/>
				<xacro:cylinder_inercja m="1" R="0.1" L="0.2"/>
			</inertial>
	</link>


	<link name="link_6">
		<visual>
			<origin xyz="0 0.1 0" rpy="1.57 0 0"/>
			<geometry>
				<cylinder length="0.1" radius="0.04"/>
			</geometry>
			<material name="grey">
				<color rgba="0.53 0.55 0.55 1"/>
			</material>
		</visual>

		<collision>
			<geometry>
				<cylinder length="0.1" radius="0.04"/>
			</geometry>
			<origin rpy="0 0 0" xyz="0 0.1 0"/>
		</collision>
		   <inertial>
				<origin rpy="0 0 0" xyz="0 0.1 0"/>
				<mass value="1"/>
				<xacro:cylinder_inercja m="1" R="0.04" L="0.1"/>
			</inertial>
	</link>

<joint name="joint_P_1" type="revolute">
    <parent link="podstawa"/>
    <child link="link_1"/>
    <axis xyz="0 0 1"/>
    <origin rpy="0 0 0" xyz="0 0 0"/>
    <limit effort="1000.0" lower="-1.48" upper="1.48" velocity="1.0"/>
  </joint>

  <joint name="joint_1_2" type="revolute">
    <parent link="link_1"/>
    <child link="link_2"/>
    <axis xyz="0 1 0"/>
    <origin rpy="0 0 0" xyz="0 0 0"/>
    <limit effort="1000.0" lower="-0.96" upper="0.96" velocity="1.0"/>
  </joint>

  <joint name="joint_2_3" type="revolute">
    <parent link="link_2"/>
    <child link="link_3"/>
    <axis xyz="0 1 0"/>
    <origin rpy="0 0 0" xyz="0 0 1"/>
    <limit effort="1000.0" lower="-3.1" upper="3.1" velocity="1.0"/>
  </joint>

    <joint name="joint_3_4" type="revolute">
    <parent link="link_3"/>
    <child link="link_4"/>
    <axis xyz="0 1 0"/>
    <origin rpy="0 0 0" xyz="0 -0.1 0.4"/>
    <limit effort="1000.0" lower="-2.44" upper="2.44" velocity="1.0"/>
  </joint>

     <joint name="joint_4_5" type="revolute">
    <parent link="link_4"/>
    <child link="link_5"/>
    <axis xyz="0 0 1"/>
    <origin rpy="0 0 0" xyz="0 -0.1 0.25"/>
    <limit effort="1000.0" lower="-6.28" upper="6.28" velocity="1.0"/>
  </joint>

    <joint name="joint_5_6" type="revolute">
    <parent link="link_5"/>
    <child link="link_6"/>
    <axis xyz="0 1 0"/>
    <origin rpy="0 0 0" xyz="0 0.05 0"/>
    <limit effort="1000.0" lower="-6.28" upper="6.28" velocity="1.0"/>
  </joint>

</robot>
